Workbook
Name UPDATE: '[1]Data Sheet'!$E$1
Name UPDATE: #REF!

Sheet Dashboard
B12: Index | J12: Valuation Method | K12: Share Price | L12: Weightage
B13: S.No. | C13: Sheet | J13: DCF Valuation | K13: =DCF!L15 -> 145.55223 | L13: 0.5
B14: 1 | C14: Drivers | J14: Relative Valutation (Enterprise Multiple) | K14: ='Relative Valuation'!N31 -> 966.97722 | L14: 0.25
B15: 2 | C15: Balancesheet | J15: Relative Valutation (Equity Multiple) | K15: ='Relative Valuation'!P31 -> 1041.9989 | L15: 0.25
B16: 3 | C16: Cash Flow
B17: 4 | C17: Assumptions and Analysis | J17: Final Blended Fair Value | K17: =SUMPRODUCT(K13:K15,L13:L15) -> 575.02014
B18: 5 | C18: Profit&Loss Forecast | J18: Current Market Price (CMP) | K18: =DCF!L14 -> 1733.33
B19: 6 | C19: Working Capital&Capex | J19: Upside/(Downside) | K19: =(K17-K18)/K18 -> -0.66825698
B20: 7 | C20: Beta | J20: Recommendation | K20: =IF(K19<-20%,"Sell","Buy") -> Sell
B21: 8 | C21: WACC
B22: 9 | C22: DCF
B23: 10 | C23: Relative Valuation
B24: 11 | C24: DDM

Sheet Drivers
B2: Company | C2: Concord Biotech Ltd
B3: Currency | C3: INR
B4: Domestic Country | C4: India
B5: Corporate Tax rate | C5: 0.25
B7: S.No. | C7: Reasons to choose
B8: 1 | C8: Pharma Industry currently navigating a period of significant change, driven by a convergence of global geopolitical shifts and rapid technological advancements.
B9: 2 | C9: Niche Market Leadership(Ferementation based Products)
B10: 3 | C10: Net Debt Free Company and Historical Good Return
B11: 4 | C11: Growth-Oriented Investments
B12: 5 | C12: Nuanced Financial Story

Sheet Balancesheet
A1: Balancesheet(in crore rupees) | I1: 100
A2: Source: Annual Report
A3: Particulars | B3: 44256 | C3: 44621 | D3: 44986 | E3: 45352 | F3: 45717
A5: ASSETS
A6: (1) Non-current Assets
A7: Property, Plant and Equipment | B7: 537.6478 | C7: 568.0305 | D7: 592.5226 | E7: 571.7327 | F7: 791.805
A8: Capital Work in progress | B8: 17.9466 | C8: 74.1552 | D8: 172.6971 | E8: 211.4824 | F8: 50.131
A9: Other Intangible Assets | B9: 6.4168 | C9: 3.577 | D9: 0.1977 | E9: 0.3197 | F9: 0.5961
A10: Right of use assets | B10: 2.1533 | C10: 1.3684 | D10: 0.2599 | E10: 3.2634 | F10: 2.2843
A11: Intangible Assets under development | B11: 0 | C11: 0 | D11: 0 | E11: 0 | F11: 0.526
A12: Financial Assets | B12: 0 | C12: 0 | D12: 0 | E12: 0 | F12: 0
A13: (i) Investments | B13: 0.6652 | C13: 0.9208 | D13: 0.7898 | E13: 0.6652 | F13: 18.6542
A14: (ii) Other Financial Assets | B14: 2.772 | C14: 2.4956 | D14: 10.1951 | E14: 4.9695 | F14: 20.5641
A15: Other Non- Current Assets | B15: 6.3938 | C15: 26.6394 | D15: 7.6195 | E15: 7.9799 | F15: 12.6007
A16: Income Tax assets(net) | B16: 1.7032 | C16: 3.6045 | D16: 2.6652 | E16: 2.6712 | F16: 1.7766
A17: Total Non Current Assets(A) | B17: =SUM(B7:B16) -> 575.6987 | C17: =SUM(C7:C16) -> 680.7914 | D17: =SUM(D7:D16) -> 786.9469 | E17: =SUM(E7:E16) -> 803.084 | F17: =SUM(F7:F16) -> 898.938
A18: (2) Current Assets
A19: Inventories | B19: 153.6061 | C19: 195.1179 | D19: 212.3147 | E19: 207.9538 | F19: 239.6672
A20: Financial Assets | B20: 0 | C20: 0 | D20: 0 | E20: 0 | F20: 0
A21: (i) Investments | B21: 140.9855 | C21: 73.4733 | D21: 136.9301 | E21: 243.7019 | F21: 316.5448
A22: (ii) Trade Receivables | B22: 177.5169 | C22: 232.1742 | D22: 273.7576 | E22: 349.6089 | F22: 521.6515
A23: (iii) Cash and cash equivalents | B23: 5.1442 | C23: 0.6669 | D23: 3.4992 | E23: 15.1421 | F23: 0.9045
A24: (iv) Bank balances other than(iii) | B24: 55.6757 | C24: 88.2648 | D24: 39.9477 | E24: 31.8823 | F24: 0.2786
A25: (v) Other Financial Assets | B25: 22.6333 | C25: 21.9822 | D25: 36.599 | E25: 19.4488 | F25: 40.8319
A26: Other current assets | B26: 51.5843 | C26: 20.9876 | D26: 24.6518 | E26: 28.4933 | F26: 15.3637
A27: Total Current Assets | B27: =SUM(B19:B26) -> 607.146 | C27: =SUM(C19:C26) -> 632.6669 | D27: =SUM(D19:D26) -> 727.7001 | E27: =SUM(E19:E26) -> 896.2311 | F27: =SUM(F19:F26) -> 1135.2422
A28: Total assets | B28: =SUM(B17,B27) -> 1182.8447 | C28: =SUM(C17,C27) -> 1313.4583 | D28: =SUM(D17,D27) -> 1514.647 | E28: =SUM(E17,E27) -> 1699.3151 | F28: =SUM(F17,F27) -> 2034.1802
A29: Equity and Liabilities
A30: Equity
A31: (a) Equity Share Capital | B31: 9.5106 | C31: 9.5106 | D31: 10.4616 | E31: 10.4616 | F31: 10.4616
A32: (b) Other Equity | B32: 990.1604 | C32: 1097.6494 | D32: 1281.5188 | E32: 1514.7905 | F32: 1802.1846
A33: Total Equity(A) | B33: =SUM(B31:B32) -> 999.671 | C33: =SUM(C31:C32) -> 1107.16 | D33: =SUM(D31:D32) -> 1291.9804 | E33: =SUM(E31:E32) -> 1525.2521 | F33: =SUM(F31:F32) -> 1812.6462
A34: LIABILITIES
A35: I. Non-current liabilities
A36: (a) Financial Liabilities
A37: (i) Borrowings | B37: 56.25 | C37: 31.2486 | D37: 6.2356 | E37: 0 | F37: 0
A38: (ii) Lease Liabilities | B38: 1.6332 | C38: 0.3107 | D38: 0.1638 | E38: 1.887 | F38: 0.6298
A39: (b) Provisions | B39: 2.0984 | C39: 1.8741 | D39: 2.2966 | E39: 1.9561 | F39: 2.8199
A40: (c) Deferred Tax Liabilities | B40: 17.4532 | C40: 20.9708 | D40: 23.439 | E40: 28.0645 | F40: 34.0217
A41: Total Non Current Liabilities(B) | B41: =SUM(B37:B40) -> 77.4348 | C41: =SUM(C37:C40) -> 54.4042 | D41: =SUM(D37:D40) -> 32.135 | E41: =SUM(E38:E40) -> 31.9076 | F41: =SUM(F38:F40) -> 37.4714
...

Sheet Cash Flow 
A1: ='[2]Balance Sheet'!A1 -> CONCORD BIOTECH LTD | E1: SCREENER.IN
A3: Narration | B3: 44256 | C3: 44621 | D3: 44986 | E3: 45352 | F3: 45717
A4: Cash from Operating Activity | B4: 166.81 | C4: 207.47 | D4: 246 | E4: 265.47 | F4: 244.52
A5: Cash from Investing Activity | B5: -195.44 | C5: -111.79 | D5: -157.95 | E5: -154.61 | F5: -159.99
A6: Cash from Financing Activity | B6: 31.37 | C6: -100.16 | D6: -85.22 | E6: -99.21 | F6: -98.77
A7: Net Cash Flow | B7: 2,74 | C7: -4.48 | D7: 2.83 | E7: 11.64 | F7: -14.24
A8: Changes in w.c | C8: ='Working capital and Capex'!C7-'Working capital and Capex'!B7 -> 59.4607 | D8: ='Working capital and Capex'!D7-'Working capital and Capex'!C7 -> 48.0858 | E8: ='Working capital and Capex'!E7-'Working capital and Capex'!D7 -> 70.8551 | F8: ='Working capital and Capex'!F7-'Working capital and Capex'!E7 -> 185.1515
A9: Capex | B9: 138.47 | C9: 135.22 | D9: 231.17 | E9: 241.61 | F9: 113.97

Sheet Assumptions and Analysis
A1: 1 | B1: About the Stock
A2: (i) | B2: Supplies to 70+ countries including the U.S., EU, Japan, and emerging markets.
A3: (ii) | B3: Biopharmaceutical company specializing in fermentation-based APIs (Active Pharmaceutical Ingredients) and formulations
A4: (iii) | B4: Plays into “China+1” strategy as global pharma looks to diversify supply chains.
A6: 2 | B6: Performance Highlights:
A7: (i) | B7: Very strong FY2025: +18% YoY full-year revenue, high profitability, and substantial dividend payout.
A8: (ii) | B8: Q4 surges: Exceptional momentum in the final quarter (+35% revenue, +48% PAT, increased margins).
A9: (iii) | B9: Quarterly contrast: Q3 was a lull, with flat revenue and reduced margins.
A10: (iv) | B10: Dividend focus: Final dividend of ₹10.70 per share reflects strong cash flow and shareholder returns.
A12: 3 | B12: Key Triggers for Future Performance:
A13: (i) | B13: Global Biotechnology market is poised for explosive growth.
A14: (ii) | B14: The company has commissioned a new injectable manufacturing facility, established two new subsidiaries (Stellon Biotech in the U.S. and Concord Lifegen in India) to strengthen its market presence, and invested in a U.S.-based rare disease company.
A15: (iii) | B15: India's Bioe3 policy and increased budgetary allocations signal a supportive regulatory environment that provides "favourable impetus" for the sector's growth.
A17: 4 | B17: Recent Events and key Risks:
A18: (i) | B18: The company successfully commissioned and began commercial production at a new state-of-the-art injectable facility at Valthera in Q4 FY25.
A19: (ii) | B19: a robust pipeline of more than 10 new API products planned for commissioning over the next 5-7 years.
A21: 5 | B21: Other Highlights:
A22: (i) | B22: Concord’s new Valthera injectable plant (commissioned Q4 FY25), USFDA approval of teriflunomide tablets (7 mg/14 mg) opening a ~$402 M US market, expansion into the US/EU via a new marketing arm, and a ramp-up of CDMO contracts are key growth drivers.
A23: (ii) | B23: Two new fermentation APIs were commercialized in FY2024 (immunosuppressant & anti-infective). The API portfolio now counts 30 products, with 10+ more in development.
A24: (iii) | B24: The company has begun small contract-manufacturing supply to a U.S. customer (H1 FY26) This diversifies revenue but likely at lower margins.
A25: (iv) | B25: The Limbasi campus (Gujarat) has 800 m³ fermentation capacity and was inspected/approved by FDA. Utilization is currently ~30–35%. Management notes 170 acres are available for future growth, implying potential new fermentation lines later if demand warrants.
A27: 6 | B27: Assumptions:
A28: (i) | B28: Company is going concern and terminal growth rate has been assumed to be 4% because the global pharmaceutical industry is expected to grow at 4–6% CAGR long term, Indian pharma at 8–10% (but Concord is already niche, so can’t sustain 8% forever).
A29: (ii) | B29: Revenue growth assumptions are based on identified future performance drivers like the global market's explosive growth, increasing prevalance of chronic diseases, growing demand for personalized medicine
A30: (iii) | B30: Historical operating expenses have remained broadly stable as a percentage of revenue over the past 4–5 years; therefore, the historical average percentage has been used for forecasting.
A31: (iv) | B31: Weekly return of Nifty 500 for past 2 years has been taken to calculate market return and beta because risk free rate has also been taken for past 10-yr govt bond yield( as of 25th august, 2025)
A32: (v) | B32: Given the company's negligible debt relative to its equity value, WACC is approximately equal to the cost of equity.
A33: (vi) | B33: Fixed Asset Turnover Ratio: Historical average of 1.145×.
A34: (vii) | B34: Other income has been taken as average of past 5 years.
A35: (viii) | B35: Four comparable companies were selected based on market capitalization, business exposure and availability of comparable valuation data.

Sheet Profit and Loss forecast
A1: INCOME STATEMENT(in rupee crores) | L1: 100
A2: Source: Annual Report
B3: Historical Results | G3: Forcasted period
A4: Particulars | B4: =Balancesheet!B3 -> 44256 | C4: =Balancesheet!C3 -> 44621 | D4: =Balancesheet!D3 -> 44986 | E4: =Balancesheet!E3 -> 45352 | F4: =Balancesheet!F3 -> 45717 | G4: 46082 | H4: 46447 | I4: 46813 | J4: 47178 | K4: 47543
A6: Income
A7: Revenue from Operations | B7: 616.9432 | C7: 712.9335 | D7: 853.1682 | E7: 1016.9392 | F7: 1200.0869 | G7: =F7*(1+G8) -> 1440.1043 | H7: =G7*(1+H8) -> 1756.9272 | I7: =H7*(1+I8) -> 2161.0205 | J7: =I7*(1+J8) -> 2658.0552 | K7: =J7*(1+K8) -> 3295.9884
A8: y-o-y growth % | C8: =C7/B7-1 -> 0.15559017 | D8: =D7/C7-1 -> 0.19670095 | E8: =E7/D7-1 -> 0.19195629 | F8: =F7/E7-1 -> 0.180097 | G8: 0.2 | H8: 0.22 | I8: 0.23 | J8: 0.23 | K8: 0.24
A10: Other Income | B10: 13.807 | C10: 23.4165 | D10: 35.3093 | E10: 33.78 | F10: 44.4467 | G10: =G11*G7 -> 48.060493 | H10: =H11*H7 -> 58.633801 | I10: =I11*I7 -> 72.119576 | J10: =J11*J7 -> 88.707078 | K10: =K11*K7 -> 109.99678
A11: % of revenue | B11: =B10/B7 -> 0.022379694 | C11: =C10/C7 -> 0.032845279 | D11: =D10/D7 -> 0.041386095 | E11: =E10/E7 -> 0.033217325 | F11: =F10/F7 -> 0.037036235 | G11: =AVERAGE($B$11:$F$11) -> 0.033372926 | H11: =AVERAGE($B$11:$F$11) -> 0.033372926 | I11: =AVERAGE($B$11:$F$11) -> 0.033372926 | J11: =AVERAGE($B$11:$F$11) -> 0.033372926 | K11: =AVERAGE($B$11:$F$11) -> 0.033372926
A13: TOTAL INCOME | B13: =SUM(B7,B10) -> 630.7502 | C13: =SUM(C7,C10) -> 736.35 | D13: =SUM(D7,D10) -> 888.4775 | E13: =SUM(E7,E10) -> 1050.7192 | F13: =SUM(F7,F10) -> 1244.5336 | G13: =SUM(G7,G10) -> 1488.1648 | H13: =SUM(H7,H10) -> 1815.561 | I13: =SUM(I7,I10) -> 2233.1401 | ... K13: =SUM(K7,K10) -> 3405.9852
A15: Expenses
A16: Cost of materials consumed | B16: 131.1682 | C16: 157.2574 | D16: 167.0715 | E16: 184.5371 | F16: 264.3126 | G16: =G17*G7 -> 296.86897 | H16: =H17*H7 -> 359.90817 | I16: =I17*I7 -> 435.88977 | J16: =J17*J7 -> 539.27067 | K16: =K17*K7 -> 682.8146
A17: % of revenue | B17: =B16/B7 -> 0.21260985 | C17: =C16/C7 -> 0.22057794 | D17: =D16/D7 -> 0.19582481 | E17: =E16/E7 -> 0.18146326 | F17: =F16/F7 -> 0.22024455 | G17: =AVERAGE(B17:F17) -> 0.20614408 | H17: =AVERAGE(C17:G17) -> 0.20485093 | I17: =AVERAGE(D17:H17) -> 0.20170552 | J17: =AVERAGE(E17:I17) -> 0.20288167 | K17: =AVERAGE(F17:J17) -> 0.20716535
A19: Purchases of stock in-trade | B19: 19.4457 | C19: 30.7334 | D19: 28.7687 | E19: 56.7389 | F19: 55.9872 | G19: =G20*G7 -> 60.713087 | H19: =H20*H7 -> 77.80849 | I19: =I20*I7 -> 96.213718 | J19: =J20*J7 -> 124.08561 | K19: =K20*K7 -> 147.86024
A20: % of revenue | B20: =B19/B7 -> 0.031519433 | C20: =C19/C7 -> 0.043108368 | D20: =D19/D7 -> 0.033719846 | E20: =E19/E7 -> 0.055793798 | F20: =F19/F7 -> 0.046652622 | G20: =AVERAGE(B20:F20) -> 0.042158813 | H20: =AVERAGE(C20:G20) -> 0.044286689 | I20: =AVERAGE(D20:H20) -> 0.044522354 | J20: =AVERAGE(E20:I20) -> 0.046682855 | K20: =AVERAGE(F20:J20) -> 0.044860667
A22: Changes in inventories of finished goods, work-in -progress and stock-in-trade | B22: -39.0456 | C22: -23.9801 | D22: -15.632 | E22: -12.0779 | F22: -14.7867 | G22: =G23*G7 -> -40.163067 | H22: =H23*H7 -> -36.559964 | I22: =I23*I7 -> -39.424969 | J22: =J23*J7 -> -48.45092 | K22: =K23*K7 -> -64.265864
A23: % of revenue | B23: =B22/B7 -> -0.063288808 | C23: =C22/C7 -> -0.033635816 | D23: =D22/D7 -> -0.018322296 | E23: =E22/E7 -> -0.011876718 | F23: =F22/F7 -> -0.012321358 | G23: =AVERAGE(B23:F23) -> -0.027888999 | H23: =AVERAGE(C23:G23) -> -0.020809037 | I23: =AVERAGE(D23:H23) -> -0.018243682 | J23: =AVERAGE(E23:I23) -> -0.018227959 | K23: =AVERAGE(F23:J23) -> -0.019498207
A25: Employee benefits expense | B25: 69.4692 | C25: 95.6945 | D25: 110.2785 | E25: 123.0467 | F25: 138.9336 | G25: =G26*G7 -> 176.51445 | H25: =H26*H7 -> 215.34763 | I25: =I26*I7 -> 264.87759 | J25: =J26*J7 -> 325.79943 | K25: =K26*K7 -> 403.99129
A26: % of revenue | B26: =B25/B7 -> 0.11260226 | C26: =C25/C7 -> 0.1342264 | D26: =D25/D7 -> 0.12925763 | E26: =E25/E7 -> 0.12099711 | F26: =F25/F7 -> 0.11576962 | G26: =AVERAGE($B$26:$F$26) -> 0.1225706 | H26: =AVERAGE($B$26:$F$26) -> 0.1225706 | I26: =AVERAGE($B$26:$F$26) -> 0.1225706 | J26: =AVERAGE($B$26:$F$26) -> 0.1225706 | K26: =AVERAGE($B$26:$F$26) -> 0.1225706
A28: Finance costs | B28: 0.6653 | C28: 5.4836 | D28: 4.5103 | E28: 2.5519 | F28: 0.5293 | G28: 0 | H28: 0 | I28: 0 | J28: 0 | K28: 0
A30: Depreciation and Amortization expense | B30: 27.5228 | C30: 50.0508 | D30: 54.0324 | E30: 53.5915 | F30: 54.3735 | G30: =G31*'Working capital and Capex'!G20 -> 78.872442 | H30: =H31*'Working capital and Capex'!H20 -> 96.224379 | I30: =I31*'Working capital and Capex'!I20 -> 118.35599 | J30: =J31*'Working capital and Capex'!J20 -> 145.57786 | K30: =K31*'Working capital and Capex'!K20 -> 180.51655
A31: % of fixed assets | B31: =B30/'Working capital and Capex'!B20 -> 0.040707108 | C31: =C30/'Working capital and Capex'!C20 -> 0.071170657 | D31: =D30/'Working capital and Capex'!D20 -> 0.065597773 | E31: =E30/'Working capital and Capex'!E20 -> 0.06589043 | F31: =F30/'Working capital and Capex'!F20 -> 0.060029809 | G31: =AVERAGE($B$31:$F$31) -> 0.060679155 | H31: =AVERAGE($B$31:$F$31) -> 0.060679155 | I31: =AVERAGE($B$31:$F$31) -> 0.060679155 | J31: =AVERAGE($B$31:$F$31) -> 0.060679155 | K31: =AVERAGE($B$31:$F$31) -> 0.060679155
A33: Other expenses | B33: 108.3565 | C33: 179.9533 | D33: 219.394 | E33: 233.133 | F33: 249.3087 | G33: =G34*G7 -> 323.2144 | H33: =H34*H7 -> 394.32157 | I33: =I34*I7 -> 485.01553 | J33: =J34*J7 -> 596.5691 | K33: =K34*K7 -> 739.74568
A34: % of revenue | B34: =B33/B7 -> 0.17563448 | C34: =C33/C7 -> 0.25241246 | D34: =D33/D7 -> 0.25715211 | E34: =E33/E7 -> 0.22924969 | F34: =F33/F7 -> 0.20774221 | G34: =AVERAGE($B$34:$F$34) -> 0.22443819 | H34: =AVERAGE($B$34:$F$34) -> 0.22443819 | I34: =AVERAGE($B$34:$F$34) -> 0.22443819 | J34: =AVERAGE($B$34:$F$34) -> 0.22443819 | K34: =AVERAGE($B$34:$F$34) -> 0.22443819
A35: Total Expenses | B35: =SUM(B16,B19,B22,B25,B28,B30,B33) -> 317.5821 | C35: =SUM(C16,C19,C22,C25,C28,C30,C33) -> 495.1929 | D35: =SUM(D16,D19,D22,D25,D28,D30,D33) -> 568.4234 | E35: =SUM(E16,E19,E22,E25,E28,E30,E33) -> 641.5212 | F35: =SUM(F16,F19,F22,F25,F28,F30,F33) -> 748.6582 | G35: =SUM(G16,G19,G22,G25,G28,G30,G33) -> 896.02028 | H35: =SUM(H16,H19,H22,H25,H28,H30,H33) -> 1107.0503 | I35: =SUM(I16,I19,I22,I25,I28,I30,I33) -> 1360.9276 | ... K35: =SUM(K16,K19,K22,K25,K28,K30,K33) -> 2090.6625
A36: PROFIT BEFORE TAX | B36: =B13-B35 -> 313.1681 | C36: =C13-C35 -> 241.1571 | D36: =D13-D35 -> 320.0541 | E36: =E13-E35 -> 409.198 | F36: =F13-F35 -> 495.8754 | G36: =G13-G35 -> 592.14449 | H36: =H13-H35 -> 708.51075 | I36: =I13-I35 -> 872.21244 | ... K36: =K13-K35 -> 1315.3227
A37: Tax Expenses | B37: 77.8333 | C37: 62.5893 | D37: 81.9277 | E37: 104.4618 | F37: 122.911 | G37: =G38*G36 -> 150.07362 | H37: =H38*H36 -> 179.56559 | I37: =I38*I36 -> 221.05429 | J37: =J38*J36 -> 269.63842 | K37: =K38*K36 -> 333.35655
A38: % of PBT | B38: =B37/B36 -> 0.24853521 | C38: =C37/C36 -> 0.25953746 | D38: =D37/D36 -> 0.25598079 | E38: =E37/E36 -> 0.25528424 | F38: =F37/F36 -> 0.2478667 | G38: =AVERAGE($B$38:$F$38) -> 0.25344088 | H38: =AVERAGE($B$38:$F$38) -> 0.25344088 | I38: =AVERAGE($B$38:$F$38) -> 0.25344088 | J38: =AVERAGE($B$38:$F$38) -> 0.25344088 | K38: =AVERAGE($B$38:$F$38) -> 0.25344088
A39: PROFIT AFTER TAX | B39: =B36-B37 -> 235.3348 | C39: =C36-C37 -> 178.5678 | D39: =D36-D37 -> 238.1264 | E39: =E36-E37 -> 304.7362 | F39: =F36-F37 -> 372.9644 | G39: =G36-G37 -> 442.07087 | H39: =H36-H37 -> 528.94516 | I39: =I36-I37 -> 651.15815 | ... K39: =K36-K37 -> 981.96617
A41: COGS | B41: =B16+B19+B22 -> 111.5683 | C41: =C16+C19+C22 -> 164.0107 | D41: =D16+D19+D22 -> 180.2082 | E41: =E16+E19+E22 -> 229.1981 | F41: =F16+F19+F22 -> 305.5131 | G41: =G16+G19+G22 -> 317.41899 | H41: =H16+H19+H22 -> 401.1567 | I41: =I16+I19+I22 -> 492.67852 | ... K41: =K16+K19+K22 -> 766.40897

Sheet Working capital and Capex
A1: Working Capital
B2: Historical Results | G2: Forcasted period
A3: Particular | B3: =Balancesheet!B3 -> 44256 | C3: =Balancesheet!C3 -> 44621 | D3: =Balancesheet!D3 -> 44986 | E3: =Balancesheet!E3 -> 45352 | F3: =Balancesheet!F3 -> 45717 | G3: 46082 | H3: 46447 | I3: 46813 | J3: 47178 | K3: 47543
A4: Inventory | B4: =Balancesheet!B19 -> 153.6061 | C4: =Balancesheet!C19 -> 195.1179 | D4: =Balancesheet!D19 -> 212.3147 | E4: =Balancesheet!E19 -> 207.9538 | F4: =Balancesheet!F19 -> 239.6672 | G4: =G11*'Profit and Loss forecast'!G41/365 -> 232.53243 | H4: =H11*'Profit and Loss forecast'!H41/365 -> 293.87637 | I4: =I11*'Profit and Loss forecast'!I41/365 -> 360.92274 | J4: =J11*'Profit and Loss forecast'!J41/365 -> 450.46276 | K4: =K11*'Profit and Loss forecast'!K41/365 -> 561.45015
A5: Trade Receivables | B5: =Balancesheet!B22 -> 177.5169 | C5: =Balancesheet!C22 -> 232.1742 | D5: =Balancesheet!D22 -> 273.7576 | E5: =Balancesheet!E22 -> 349.6089 | F5: =Balancesheet!F22 -> 521.6515 | G5: =G12*'Profit and Loss forecast'!G13/365 -> 450.01425 | H5: =H12*'Profit and Loss forecast'!H13/365 -> 549.01739 | I5: =I12*'Profit and Loss forecast'!I13/365 -> 675.29139 | J5: =J12*'Profit and Loss forecast'!J13/365 -> 830.6084 | K5: =K12*'Profit and Loss forecast'!K13/365 -> 1029.9544
A6: Trade Payables | B6: =Balancesheet!B46 -> 46.3972 | C6: =Balancesheet!C46 -> 83.1056 | D6: =Balancesheet!D46 -> 93.8 | E6: =Balancesheet!E46 -> 94.4353 | F6: =Balancesheet!F46 -> 113.0398 | G6: ='Profit and Loss forecast'!G41*'Working capital and Capex'!G13/365 -> 107.78022 | H6: ='Profit and Loss forecast'!H41*'Working capital and Capex'!H13/365 -> 136.21351 | I6: ='Profit and Loss forecast'!I41*'Working capital and Capex'!I13/365 -> 167.28992 | J6: ='Profit and Loss forecast'!J41*'Working capital and Capex'!J13/365 -> 208.79227 | K6: ='Profit and Loss forecast'!K41*'Working capital and Capex'!K13/365 -> 260.23561
A7: Working Capital | B7: =B4+B5-B6 -> 284.7258 | C7: =C4+C5-C6 -> 344.1865 | D7: =D4+D5-D6 -> 392.2723 | E7: =E4+E5-E6 -> 463.1274 | F7: =F4+F5-F6 -> 648.2789 | G7: =G4+G5-G6 -> 574.76646 | H7: =H4+H5-H6 -> 706.68024 | I7: =I4+I5-I6 -> 868.92421 | ... K7: =K4+K5-K6 -> 1331.169
A8: Change in WC | C8: =C7-B7 -> 59.4607 | D8: =D7-C7 -> 48.0858 | E8: =E7-D7 -> 70.8551 | F8: =F7-E7 -> 185.1515 | G8: =G7-F7 -> -73.512437 | H8: =H7-G7 -> 131.91378 | I8: =I7-H7 -> 162.24396 | J8: =J7-I7 -> 203.35469 | K8: =K7-J7 -> 258.89006
A10: KPIs
A11: Inventory days (DIO) | C11: =365*AVERAGE(B4,C4)/'Profit and Loss forecast'!C41 -> 388.03645 | D11: =365*AVERAGE(C4,D4)/'Profit and Loss forecast'!D41 -> 412.61413 | E11: =365*AVERAGE(D4,E4)/'Profit and Loss forecast'!E41 -> 334.64065 | F11: =365*AVERAGE(E4,F4)/'Profit and Loss forecast'!F41 -> 267.38897 | G11: =$F$11 -> 267.38897 | H11: =$F$11 -> 267.38897 | I11: =$F$11 -> 267.38897 | J11: =$F$11 -> 267.38897 | K11: =$F$11 -> 267.38897
A12: Trade receivable days (DSO) | C12: =365*AVERAGE(B5,C5)/'Profit and Loss forecast'!C13 -> 101.53952 | D12: =365*AVERAGE(C5,D5)/'Profit and Loss forecast'!D13 -> 103.92222 | E12: =365*AVERAGE(D5,E5)/'Profit and Loss forecast'!E13 -> 108.27287 | F12: =365*AVERAGE(E5,F5)/'Profit and Loss forecast'!F13 -> 127.76274 | G12: =AVERAGE($C$12:$F$12) -> 110.37434 | H12: =AVERAGE($C$12:$F$12) -> 110.37434 | I12: =AVERAGE($C$12:$F$12) -> 110.37434 | J12: =AVERAGE($C$12:$F$12) -> 110.37434 | K12: =AVERAGE($C$12:$F$12) -> 110.37434
A13: Trade payable days (DPO) | C13: =365*AVERAGE('Working capital and Capex'!B6,'Working capital and Capex'!C6)/'Profit and Loss forecast'!C41 -> 144.10195 | D13: =365*AVERAGE('Working capital and Capex'!C6,'Working capital and Capex'!D6)/'Profit and Loss forecast'!D41 -> 179.1554 | E13: =365*AVERAGE('Working capital and Capex'!D6,'Working capital and Capex'!E6)/'Profit and Loss forecast'!E41 -> 149.88319 | F13: =365*AVERAGE('Working capital and Capex'!E6,'Working capital and Capex'!F6)/'Profit and Loss forecast'!F41 -> 123.93644 | G13: =$F$13 -> 123.93644 | H13: =$F$13 -> 123.93644 | I13: =$F$13 -> 123.93644 | J13: =$F$13 -> 123.93644 | K13: =$F$13 -> 123.93644
A15: Capex Schedule
B16: Historical Results | G16: Forcasted period
A17: Particular | B17: 44256 | C17: 44621 | D17: 44986 | E17: 45352 | F17: 45717 | G17: 46082 | H17: 46447 | I17: 46813 | J17: 47178 | K17: 47543
A18: Beginning PPE | B18: =Balancesheet!B7 -> 537.6478 | C18: =Balancesheet!C7 -> 568.0305 | D18: =Balancesheet!D7 -> 592.5226 | E18: =Balancesheet!E7 -> 571.7327 | F18: =Balancesheet!F7 -> 791.805 | G18: =F22 -> 851.4015 | H18: =G22 -> 1220.9552 | I18: =H22 -> 1489.5653 | J18: =I22 -> 1832.1653 | K18: =J22 -> 2253.5634
A19: [+] Capex | B19: ='Cash Flow '!B9 -> 138.47 | C19: ='Cash Flow '!C9 -> 135.22 | D19: ='Cash Flow '!D9 -> 231.17 | E19: ='Cash Flow '!E9 -> 241.61 | F19: ='Cash Flow '!F9 -> 113.97 | G19: =G20-G18 -> 448.42613 | H19: =H20-H18 -> 364.83452 | I19: =I20-I18 -> 460.95601 | J19: =J20-J18 -> 566.97589 | K19: =K20-K18 -> 721.37176
A20: Total Fixed Assets | B20: =SUM(B18:B19) -> 676.1178 | C20: =SUM(C18:C19) -> 703.2505 | D20: =SUM(D18:D19) -> 823.6926 | E20: =SUM(E18:E19) -> 813.3427 | F20: =SUM(F18:F19) -> 905.775 | G20: ='Profit and Loss forecast'!G13/'Working capital and Capex'!G24 -> 1299.8276 | H20: ='Profit and Loss forecast'!H13/'Working capital and Capex'!H24 -> 1585.7897 | I20: ='Profit and Loss forecast'!I13/'Working capital and Capex'!I24 -> 1950.5213 | J20: ='Profit and Loss forecast'!J13/'Working capital and Capex'!J24 -> 2399.1412 | K20: ='Profit and Loss forecast'!K13/'Working capital and Capex'!K24 -> 2974.9351
A21: [-] Less Depreciation | B21: ='Profit and Loss forecast'!B30 -> 27.5228 | C21: ='Profit and Loss forecast'!C30 -> 50.0508 | D21: ='Profit and Loss forecast'!D30 -> 54.0324 | E21: ='Profit and Loss forecast'!E30 -> 53.5915 | F21: ='Profit and Loss forecast'!F30 -> 54.3735 | G21: =G26*G20 -> 78.872442 | H21: =H26*H20 -> 96.224379 | I21: =I26*I20 -> 118.35599 | J21: =J26*J20 -> 145.57786 | K21: =K26*K20 -> 180.51655
A22: Ending PPE (Closing Balance) | B22: =B20-B21 -> 648.595 | C22: =C20-C21 -> 653.1997 | D22: =D20-D21 -> 769.6602 | E22: =E20-E21 -> 759.7512 | F22: =F20-F21 -> 851.4015 | G22: =G20-G21 -> 1220.9552 | H22: =H20-H21 -> 1489.5653 | I22: =I20-I21 -> 1832.1653 | ... K22: =K20-K21 -> 2794.4186
A24: Fixed Asset turnover ratio | B24: ='Profit and Loss forecast'!B13/'Working capital and Capex'!B20 -> 0.93289986 | C24: ='Profit and Loss forecast'!C13/'Working capital and Capex'!C20 -> 1.0470664 | D24: ='Profit and Loss forecast'!D13/'Working capital and Capex'!D20 -> 1.0786518 | E24: ='Profit and Loss forecast'!E13/'Working capital and Capex'!E20 -> 1.291853 | F24: ='Profit and Loss forecast'!F13/'Working capital and Capex'!F20 -> 1.3739986 | G24: =AVERAGE($B$24:$F$24) -> 1.1448939 | H24: =AVERAGE($B$24:$F$24) -> 1.1448939 | I24: =AVERAGE($B$24:$F$24) -> 1.1448939 | J24: =AVERAGE($B$24:$F$24) -> 1.1448939 | K24: =AVERAGE($B$24:$F$24) -> 1.1448939
A26: Dep as % of PPE Rough work (to verify) | B26: =B21/B20 -> 0.040707108 | C26: =C21/C20 -> 0.071170657 | D26: =D21/D20 -> 0.065597773 | E26: =E21/E20 -> 0.06589043 | F26: =F21/F20 -> 0.060029809 | G26: =AVERAGE($B$26:$F$26) -> 0.060679155 | H26: =AVERAGE($B$26:$F$26) -> 0.060679155 | I26: =AVERAGE($B$26:$F$26) -> 0.060679155 | J26: =AVERAGE($B$26:$F$26) -> 0.060679155 | K26: =AVERAGE($B$26:$F$26) -> 0.060679155

Sheet Beta
B1: Source: Investing.com
B4: Concord Biotech Ltd. Weekly returns | F4: Nifty 500 Weekly returns
B6: Date | C6: Price | D6: Weeky Return | F6: Price | G6: Weeky Return | I6: Beta | J6: =SLOPE(D8:D110,G8:G110) -> 1.18107 | K6: 2-yr weekly return
B7: 45886 | C7: 1767.6 | F7: 22991.3 | I7: Rm(Market Return) | J7: =_xlfn.RRI(5,C110,C7) -> 0.12727138
B8: 45879 | C8: 1642.5 | D8: =C8/C7-1 -> -0.070773931 | F8: 22680.25 | G8: =F8/F7-1 -> -0.013529031 | I8: Rf(Risk free rate of return) | J8: 0.065
B9: 45872 | C9: 1598 | D9: =C9/C8-1 -> -0.027092846 | F9: 22443.15 | G9: =F9/F8-1 -> -0.010454029
B10: 45865 | C10: 1740.7 | D10: =C10/C9-1 -> 0.089299124 | F10: 22673.65 | G10: =F10/F9-1 -> 0.010270394
B11: 45858 | C11: 1880.8 | D11: =C11/C10-1 -> 0.080484862 | F11: 23014.8 | G11: =F11/F10-1 -> 0.0150461
B12: 45851 | C12: 1893.9 | D12: =C12/C11-1 -> 0.0069651212 | F12: 23275.15 | G12: =F12/F11-1 -> 0.011312286
B13: 45844 | C13: 1803.3 | D13: =C13/C12-1 -> -0.047837795 | F13: 23282.7 | G13: =F13/F12-1 -> 0.00032438029
B14: 45837 | C14: 1737.7 | D14: =C14/C13-1 -> -0.036377752 | F14: 23562.45 | G14: =F14/F13-1 -> 0.012015359
B15: 45830 | C15: 1823.5 | D15: =C15/C14-1 -> 0.049375611 | F15: 23620.15 | G15: =F15/F14-1 -> 0.0024488116
B16: 45823 | C16: 1837.3 | D16: =C16/C15-1 -> 0.007567864 | F16: 23041.1 | G16: =F16/F15-1 -> -0.024515086
B17: 45816 | C17: 2109.7 | D17: =C17/C16-1 -> 0.14826104 | F17: 22906.2 | G17: =F17/F16-1 -> -0.0058547552
B18: 45809 | C18: 1926.6 | D18: =C18/C17-1 -> -0.086789591 | F18: 23165.1 | G18: =F18/F17-1 -> 0.011302617
B19: 45802 | C19: 1748.5 | D19: =C19/C18-1 -> -0.092442645 | F19: 22801.95 | G19: =F19/F18-1 -> -0.0156766
B20: 45795 | C20: 1535.9 | D20: =C20/C19-1 -> -0.12158993 | F20: 22781.05 | G20: =F20/F19-1 -> -0.00091658827
... B110: 45165 | C110: 971.05 | D110: =C110/C109-1 -> -0.042593049 | F110: 17074.55 | G110: =F110/F109-1 -> -0.023611218

Sheet WACC
C2: Current capital structure
C3: Particular | D3: Market Value | E3: Ratio | F3: Share price (as of 25th August 2025) | G3: # of outstanding shares
C4: Equity | D4: =(F4*G4) -> 181999650000 | E4: =D4/D6 -> 0.99997912 | F4: 1733.33 | G4: 105000000
C5: Debt | D5: =3800000 -> 3800000 | E5: =D5/D6 -> 2.0878725e-05
C6: Equity + Debt | D6: =D4+D5 -> 182003450000
C9: Cost of equity
C10: Particular | D10: Market Value | E10: Reference
C11: Rf | D11: =Beta!J8 -> 0.065 | E11: 10 Year Government Bond Yield (as of 25th August 2025)
C12: Rm | D12: =Beta!J7 -> 0.12727138 | E12: Nifty 500
C13: Beta | D13: =Beta!J6 -> 1.18107 | E13: Regression analysis of returns v/s Nifty 500 returns
C14: Ke | D14: =D11+D13*(D12-D11) -> 0.13854685 | E14: Rf+B(Rm-Rf)
C17: Cost of debt (Post-Tax)
C18: Particular | D18: Market Value | E18: Reference
C19: Cost of debt (kd) | D19: 0.085 | E19: Indian mid-cap pharma/biotech firms without major leverage typically borrow at 8–10% p.a. in INR.
C20: Tax rate | D20: 0.25 | E20: Annual report( also average tax rate over the yeas hovers around 25%)
C21: Kd (post tax) | D21: =D19*(1-D20) -> 0.06375
C23: WACC | D23: =D14*E4+E5*D21 -> 0.13854529

Sheet DCF
C3: Free Cashflow to the firm (FCFF)
C4: Particulars | D4: 46082 | E4: 46447 | F4: 46813 | G4: 47178 | H4: 47543
C5: EBIT | D5: ='Profit and Loss forecast'!G36 -> 592.14449 | E5: ='Profit and Loss forecast'!H36 -> 708.51075 | F5: ='Profit and Loss forecast'!I36 -> 872.21244 | G5: ='Profit and Loss forecast'!J36 -> 1063.9105 | H5: ='Profit and Loss forecast'!K36 -> 1315.3227
C6: Tax | D6: ='Profit and Loss forecast'!G37 -> 150.07362 | E6: ='Profit and Loss forecast'!H37 -> 179.56559 | F6: ='Profit and Loss forecast'!I37 -> 221.05429 | G6: ='Profit and Loss forecast'!J37 -> 269.63842 | H6: ='Profit and Loss forecast'!K37 -> 333.35655
C7: EBIT - Tax (NOPAT) | D7: =D5-D6 -> 442.07087 | E7: =E5-E6 -> 528.94516 | F7: =F5-F6 -> 651.15815 | G7: =G5-G6 -> 794.27211 | H7: =H5-H6 -> 981.96617
C8: [+] Depreciation | D8: ='Profit and Loss forecast'!G30 -> 78.872442 | E8: ='Profit and Loss forecast'!H30 -> 96.224379 | F8: ='Profit and Loss forecast'!I30 -> 118.35599 | G8: ='Profit and Loss forecast'!J30 -> 145.57786 | H8: ='Profit and Loss forecast'!K30 -> 180.51655
C9: [-] Capex | D9: ='Working capital and Capex'!G19 -> 448.42613 | E9: ='Working capital and Capex'!H19 -> 364.83452 | F9: ='Working capital and Capex'!I19 -> 460.95601 | G9: ='Working capital and Capex'!J19 -> 566.97589 | H9: ='Working capital and Capex'!K19 -> 721.37176
C10: [-] Net change in WC | D10: ='Working capital and Capex'!G8 -> -73.512437 | E10: ='Working capital and Capex'!H8 -> 131.91378 | F10: ='Working capital and Capex'!I8 -> 162.24396 | G10: ='Working capital and Capex'!J8 -> 203.35469 | H10: ='Working capital and Capex'!K8 -> 258.89006
C11: FCFF | D11: =D7+D8-D9-D10 -> 146.02962 | E11: =E7+E8-E9-E10 -> 128.42124 | F11: =F7+F8-F9-F10 -> 146.31417 | G11: =G7+G8-G9-G10 -> 169.51939 | H11: =H7+H8-H9-H10 -> 182.2209
C14: Discounted Cash Flow Valuation | I14: Current Market Price | L14: 1733.33
I15: DCF Valuation Price | L15: =D25 -> 145.55223
C16: WACC | D16: =WACC!D23 -> 0.13854529 | I16: Upside/(Downside) Potential | L16: =(L15-L14)/L14 -> -0.9160274
C17: PV of FCFF | D17: {=NPV(D16,D11:H11)} -> 522.59441
C18: Terminal/Perpetuity Growth rate | D18: 0.04
C19: Terminal Value | D19: =H11*(1+D18)/(D16-D18) -> 1923.0724
C20: PV of Terminal Value | D20: =D19/(1+D16)^5 -> 1005.1806
C21: Enterprise Value | D21: =D20+D17 -> 1527.775
C22: Net Debt (including cash and cash equivalent) | D22: =Balancesheet!F37+Balancesheet!F44-Balancesheet!F23 -> -0.5234
C23: Equity Value | D23: =D21-D22 -> 1528.2984
C24: Number of Shares outstanding (in Cr) | D24: =105000000/10000000 -> 10.5
C25: Target Price per share | D25: =D23/D24 -> 145.55223

Sheet Relative Valuation
B1: RELATIVE VALUATION
B4: Company Name | C4: Market Data | I4: Financial Data 2024-2025 | N4: Valuation 2024-2025
C5: Price | D5: Market Cap | E5: Net Debt | F5: EV | G5: Shares Outstanding | I5: Sales | J5: EBITDA | K5: Earnings | L5: Book Value per share | N5: EV/Sales | O5: EV/EBITDA | P5: P/E | Q5: P/B
C6: (INR/share) | D6: (Cr) | E6: (Cr) | F6: (Cr) | I6: (Cr) | J6: (Cr) | K6: (Cr) | L6: (Cr)
B7: Concord Biotech Ltd | C7: 1733.33 | D7: 17936.50 | E7: =DCF!D22 -> -0.5234 | F7: 17938.29 | G7: 10.5 | I7: 1188.27 | J7: 527.93 | K7: 356.11 | L7: 173.27 | N7: 15.27 | O7: 33.66 | P7: 50.4x | Q7: 9.71
B8: Sun Pharma.Inds. | C8: 1642.9 | D8: 394306.94 | E8: 2362.19 | F8: 385337.51 | G8: 239.93 | I8: 53777.09 | J8: 17253.13 | K8: 14677.74 | L8: 300.99 | N8: =F8/I8 -> 7.1654586 | O8: =F8/J8 -> 22.334354 | P8: 34.37 | Q8: 5.3
B9: Zydus Lifesci. | C9: 990 | D9: 99461.11 | E9: 3213.2 | F9: 99717.51 | G9: 100.62 | I9: 23607.7 | J9: 7293.5 | K9: 6377.7 | L9: 238.05 | N9: 0.42009641 | O9: 13.672107 | P9: 21.36 | Q9: 4.12
B10: Mankind Pharma | C10: 2610 | D10: 107701.49 | E10: 8511.45 | F10: 115658.44 | G10: 41.27 | I10: 12925.02 | J10: 3247.31 | K10: 2626.09 | L10: 347.39 | N10: =F10/I10 -> 8.9484148 | O10: =F10/J10 -> 35.616692 | P10: 56.9 | Q10: 7.11
B11: Cipla | C11: 1591.1 | D11: 128659.07 | E11: 438.19 | F11: 128297.42 | G11: 80.78 | I11: 27811.15 | J11: 7820.56 | K11: 6713.61 | L11: 386.24 | N11: =F11/I11 -> 4.6131649 | O11: =F11/J11 -> 16.405145 | P11: 23.86 | Q11: 4.12
B13: High | N13: =MAX(N7:N11) -> 15.27 | O13: =MAX(O7:O11) -> 35.616692 | P13: =MAX(P7:P11) -> 56.9 | Q13: =MAX(Q7:Q11) -> 9.71
B14: 75th Percentile | N14: =QUARTILE(N7:N11,3) -> 8.9484148 | O14: =QUARTILE(O7:O11,3) -> 33.66 | P14: =QUARTILE(P7:P11,3) -> 45.635 | Q14: =QUARTILE(Q7:Q11,3) -> 7.11
B15: Average | N15: =AVERAGE(N7:N11) -> 7.2834269 | O15: =AVERAGE(O7:O11) -> 24.337659 | P15: =AVERAGE(P7:P11) -> 38.376667 | Q15: =AVERAGE(Q7:Q11) -> 6.072
B16: Median | N16: =MEDIAN(N7:N11) -> 7.1654586 | O16: =MEDIAN(O7:O11) -> 22.334354 | P16: =MEDIAN(P7:P11) -> 34.37 | Q16: =MEDIAN(Q7:Q11) -> 5.3
B17: 25th Percentile | N17: =QUARTILE(N7:N11,1) -> 4.6131649 | O17: =QUARTILE(O7:O11,1) -> 16.405145 | P17: =QUARTILE(P7:P11,1) -> 29.115 | Q17: =QUARTILE(Q7:Q11,1) -> 4.12
B18: Low | N18: =MIN(N7:N11) -> 0.42009641 | O18: =MIN(O7:O11) -> 13.672107 | P18: =MIN(P7:P11) -> 23.86 | Q18: =MIN(Q7:Q11) -> 4.12
B21: Concord Biotech Ltd. | N21: EV/Sales | O21: EV/EBITDA | P21: P/E | Q21: P/B
B22: Implied Enterprise Value | N22: =N$16*I7 -> 8514.4994 | O22: =O$16*J7 -> 11790.975 | P22: =P24+P23 -> 12238.977 | Q22: =Q24+Q23 -> 9641.9521
B23: Net Debt | N23: =$E$7 -> -0.5234 | O23: =$E$7 -> -0.5234 | P23: =$E$7 -> -0.5234 | Q23: =$E$7 -> -0.5234
B24: Implied Market value | N24: =N22-N23 -> 8515.0228 | O24: =O22-O23 -> 11791.499 | P24: =P16*K7 -> 12239.501 | Q24: =Q16*L7*G7 -> 9642.4755
B25: Shares outstanding | N25: =$G$7 -> 10.5 | O25: =$G$7 -> 10.5 | P25: =$G$7 -> 10.5 | Q25: =$G$7 -> 10.5
B26: Implied Value Per Share | N26: =N24/N25 -> 810.95456 | O26: =O24/O25 -> 1122.9999 | P26: =P24/P25 -> 1165.6667 | Q26: =Q24/Q25 -> 918.331
N28: =IF(N26>$C$7,"Undervalued","Overvalued") -> Overvalued | O28: =IF(O26>$C$7,"Undervalued","Overvalued") -> Overvalued | P28: =IF(P26>$C$7,"Undervalued","Overvalued") -> Overvalued | Q28: =IF(Q26>$C$7,"Undervalued","Overvalued") -> Overvalued
B29: Source: Screener.in | N29: Enterprise Multiple | P29: Equity Multiple
M30: Weightage | N30: 0.5 | O30: 0.5 | P30: 0.5 | Q30: 0.5
M31: Value | N31: =SUMPRODUCT(N26:O26,N30:O30) -> 966.97722 | P31: =SUMPRODUCT(P26:Q26,P30:Q30) -> 1041.9989

Sheet DDM
A1: Source: Screener.in
C2: Dividend Discount Model
C3: Particulars | D3: 44256 | E3: 44621 | F3: 44986 | G3: 45352 | H3: 45717 | I3: 46082 | J3: 46447 | K3: 46813 | L3: 47178 | M3: 47543
C4: EPS | D4: ='Profit and Loss forecast'!B39*10^5/WACC!$G$4 -> 0.22412838 | E4: ='Profit and Loss forecast'!C39*10^5/WACC!$G$4 -> 0.17006457 | F4: ='Profit and Loss forecast'!D39*10^5/WACC!$G$4 -> 0.22678705 | G4: ='Profit and Loss forecast'!E39*10^5/WACC!$G$4 -> 0.29022495 | H4: ='Profit and Loss forecast'!F39*10^5/WACC!$G$4 -> 0.35520419 | I4: ='Profit and Loss forecast'!G39*10^5/WACC!$G$4 -> 0.42101988 | J4: ='Profit and Loss forecast'!H39*10^5/WACC!$G$4 -> 0.5037573 | K4: ='Profit and Loss forecast'!I39*10^5/WACC!$G$4 -> 0.62015062 | ... O4: ='Profit and Loss forecast'!M39*10^5/WACC!$G$4 -> 0
C5: Dividend Payout ratio | D5: 0 | E5: 0.03 | F5: 0.3 | G5: 0.3 | H5: 0.25 | I5: =AVERAGE($D$5:$H$5) -> 0.176 | J5: =AVERAGE($D$5:$H$5) -> 0.176 | K5: =AVERAGE($D$5:$H$5) -> 0.176 | L5: =AVERAGE($D$5:$H$5) -> 0.176 | M5: =AVERAGE($D$5:$H$5) -> 0.176
C6: Dividend per share | D6: =D5*D4 -> 0 | E6: =E5*E4 -> 0.0051019371 | F6: =F5*F4 -> 0.068036114 | G6: =G5*G4 -> 0.087067486 | H6: =H5*H4 -> 0.088801048 | I6: =I5*I4 -> 0.074099498 | J6: =J5*J4 -> 0.088661285 | K6: =K5*K4 -> 0.10914651 | ... M6: =M5*M4 -> 0.16459623
C7: Dividend Growth | F7: =_xlfn.RRI(1,E6,F6) -> 12.335349 | G7: =_xlfn.RRI(1,F6,G6) -> 0.27972455 | H7: =_xlfn.RRI(1,G6,H6) -> 0.019910554 | I7: =_xlfn.RRI(1,H6,I6) -> -0.16555604 | J7: =_xlfn.RRI(1,I6,J6) -> 0.19651667 | K7: =_xlfn.RRI(1,J6,K6) -> 0.2310504 | L7: =_xlfn.RRI(1,K6,L6) -> 0.21978371 | M7: =_xlfn.RRI(1,L6,M6) -> 0.23630953
C10: Particular | D10: Values
C11: Return of Equity (Re) | D11: =WACC!D14 -> 0.13854685
C12: Growth Rate (g) | D12: =DCF!D18 -> 0.04
C13: Terminal Value | D13: =M6*(1+D12)/(D11-D12) -> 1.7370426
C14: Present Value of Terminal Value | D14: =D13/(1+D11)^5 -> 0.90793746
C15: Present Value of Future Dividends | D15: {=NPV(D11,I6:M6)} -> 0.37269493
C16: Intrinsic Value of share price (as per DDM) | D16: =SUM(D14:D15) -> 1.2806324
C18: Important Inference:- | D18: 1. As we can see above in the calculation table, the "Dividend Growth Rate" is fluctuating drastically every year for the past 6 years. Hence, using the DDM model for valuation in this particular case might not generate the required results.
